Workbook

Sheet 进攻得分
A1: Rank | B1: Team | C1: 2021 | D1: Last 3 | E1: Last 1 | F1: Home | G1: Away | H1: 2020
A2: 1 | B2: Charlotte | C2: 114.7 | D2: 109 | E2: 92 | F2: 121.8 | G2: 109 | H2: 109.6
A3: 2 | B3: New York | C3: 113 | D3: 108.3 | E3: 98 | F3: 114.5 | G3: 111.5 | H3: 106.4
A4: 3 | B4: Utah | C4: 112.8 | D4: 114 | E4: 116 | F4: 116 | G4: 110.8 | H4: 116.5
A5: 4 | B5: LA Lakers | C5: 112.3 | D5: 106 | E5: 104 | F5: 110.1 | G5: 120 | H5: 108.5
A6: 5 | B6: Golden State | C6: 111.3 | D6: 106 | E6: 114 | F6: 108.2 | G6: 115.3 | H6: 113.5
A7: 6 | B7: Indiana | C7: 111.2 | D7: 112 | E7: 111 | F7: 109.4 | G7: 113.5 | H7: 115.7
A8: 7 | B8: Portland | C8: 111 | D8: 106.7 | E8: 104 | F8: 120.5 | G8: 101.5 | H8: 116.4
A9: 8 | B9: Washington | C9: 110.9 | D9: 108.7 | E9: 100 | F9: 118 | G9: 103.8 | H9: 116.3
A10: 8 | B10: Memphis | C10: 110.9 | D10: 105.7 | E10: 108 | F10: 112.2 | G10: 109.5 | H10: 113.3
A11: 8 | B11: Miami | C11: 110.9 | D11: 110.7 | E11: 78 | F11: 109 | G11: 112.8 | H11: 107.5
A12: 11 | B12: Philadelphia | C12: 110.8 | D12: 108.3 | E12: 109 | F12: 111.4 | G12: 110 | H12: 114
A13: 12 | B13: Sacramento | C13: 109.9 | D13: 108 | E13: 112 | F13: 106.7 | G13: 111.8 | H13: 113.7
... A31: 30 | B31: Detroit | C31: 95.5 | D31: 92.7 | E31: 98 | F31: 96.2 | G31: 94.8 | H31: 106.6

Sheet 防守得分
A1: Rank | B1: Team | C1: 2021 | D1: Last 3 | E1: Last 1 | F1: Home | G1: Away | H1: 2020
A2: 1 | B2: Miami | C2: 98.4 | D2: 102.7 | E2: 95 | F2: 94.8 | G2: 102 | H2: 108.6
A3: 2 | B3: Denver | C3: 99.4 | D3: 101.7 | E3: 108 | F3: 90 | G3: 105 | H3: 111.4
A4: 3 | B4: Utah | C4: 100.1 | D4: 102 | E4: 98 | F4: 103 | G4: 98.4 | H4: 108.6
A5: 4 | B5: Toronto | C5: 100.2 | D5: 99.3 | E5: 100 | F5: 104.2 | G5: 95.2 | H5: 111.7
A6: 5 | B6: Chicago | C6: 101.2 | D6: 105.3 | E6: 103 | F6: 99.2 | G6: 103.2 | H6: 111.6
A7: 6 | B7: Golden State | C7: 101.4 | D7: 92.7 | E7: 92 | F7: 97.8 | G7: 106.3 | H7: 112.6
A8: 7 | B8: Philadelphia | C8: 102.3 | D8: 99.7 | E8: 98 | F8: 102.2 | G8: 102.5 | H8: 108.2
A9: 8 | B9: LA Clippers | C9: 104.7 | D9: 106.7 | E9: 115 | F9: 98 | G9: 113.7 | H9: 107.8
A10: 9 | B10: Cleveland | C10: 104.9 | D10: 105 | E10: 104 | F10: 107.3 | G10: 103.7 | H10: 112.3
A11: 10 | B11: Brooklyn | C11: 105 | D11: 99 | E11: 108 | F11: 100.7 | G11: 118 | H11: 112.9
A12: 11 | B12: Minnesota | C12: 106.3 | D12: 111.3 | E12: 126 | F12: 106 | G12: 108 | H12: 117.7
A13: 12 | B13: Dallas | C13: 106.4 | D13: 110.7 | E13: 108 | F13: 107.2 | G13: 105.5 | H13: 110.3
... A31: 30 | B31: Charlotte | C31: 114.9 | D31: 113.3 | E31: 114 | F31: 122 | G31: 109.2 | H31: 111.8

Sheet 篮网egular Season Table (2)
A1: Rk | B1: G | C1: Date | D1: Column1 | E1: Opp | F1: W/L | G1: Tm | H1: Opp2 | I1: Team FG | J1: Team FGA | K1: Team FG% | L1: Team 3P | M1: Team 3PA | N1: Team 3P% | O1: Team FT | P1: Team FTA | Q1: Team FT% | R1: Team ORB | S1: Team TRB | T1: Team AST | U1: Team STL | V1: Team BLK | W1: Team TOV | X1: Team PF | Y1: 2 | Z1: Opponent FG | AA1: Opponent FGA | AB1: Opponent FG% | AC1: Opponent 3P | AD1: Opponent 3PA | AE1: Opponent 3P% | AF1: Opponent FT | AG1: Opponent FTA | AH1: Opponent FT% | AI1: Opponent ORB | AJ1: Opponent TRB | AK1: Opponent AST | AL1: Opponent STL | AM1: Opponent BLK | AN1: Opponent TOV | AO1: Opponent PF
A2: 1 | B2: 1 | C2: 2020-12-22 | E2: GSW | F2: W | G2: 125 | H2: 99 | I2: 42 | J2: 92 | K2: .457 | L2: 15 | M2: 35 | N2: .429 | O2: 26 | P2: 32 | Q2: .813 | R2: 13 | S2: 57 | T2: 24 | U2: 11 | V2: 7 | W2: 20 | X2: 22 | Z2: 37 | AA2: 99 | AB2: .374 | AC2: 10 | AD2: 33 | AE2: .303 | AF2: 15 | AG2: 23 | AH2: .652 | AI2: 13 | AJ2: 47 | AK2: 26 | AL2: 6 | AM2: 6 | AN2: 18 | AO2: 24
A3: 2 | B3: 2 | C3: 2020-12-25 | D3: @ | E3: BOS | F3: W | G3: 123 | H3: 95 | I3: 41 | J3: 76 | K3: .539 | L3: 15 | M3: 29 | N3: .517 | O3: 26 | P3: 31 | Q3: .839 | R3: 9 | S3: 43 | T3: 21 | U3: 5 | V3: 10 | W3: 15 | X3: 22 | Z3: 37 | AA3: 98 | AB3: .378 | AC3: 8 | AD3: 27 | AE3: .296 | AF3: 13 | AG3: 19 | AH3: .684 | AI3: 20 | AJ3: 47 | AK3: 23 | AL3: 6 | AM3: 5 | AN3: 15 | AO3: 27
A4: 3 | B4: 3 | C4: 2020-12-27 | D4: @ | E4: CHO | F4: L | G4: 104 | H4: 106 | I4: 35 | J4: 82 | K4: .427 | L4: 17 | M4: 47 | N4: .362 | O4: 17 | P4: 25 | Q4: .680 | R4: 6 | S4: 46 | T4: 23 | U4: 4 | V4: 5 | W4: 19 | X4: 17 | Z4: 43 | AA4: 96 | AB4: .448 | AC4: 10 | AD4: 34 | AE4: .294 | AF4: 10 | AG4: 17 | AH4: .588 | AI4: 13 | AJ4: 52 | AK4: 35 | AL4: 8 | AM4: 3 | AN4: 12 | AO4: 25
A5: 4 | B5: 4 | C5: 2020-12-28 | E5: MEM | F5: L | G5: 111 | H5: 116 | I5: 41 | J5: 100 | K5: .410 | L5: 14 | M5: 42 | N5: .333 | O5: 15 | P5: 17 | Q5: .882 | R5: 13 | S5: 50 | T5: 28 | U5: 13 | V5: 6 | W5: 17 | X5: 20 | Z5: 42 | AA5: 98 | AB5: .429 | AC5: 10 | AD5: 29 | AE5: .345 | AF5: 22 | AG5: 29 | AH5: .759 | AI5: 16 | AJ5: 56 | AK5: 20 | AL5: 10 | AM5: 4 | AN5: 19 | AO5: 17
A6: 5 | B6: 5 | C6: 2020-12-30 | E6: ATL | F6: W | G6: 145 | H6: 141 | I6: 54 | J6: 100 | K6: .540 | L6: 19 | M6: 41 | N6: .463 | O6: 18 | P6: 23 | Q6: .783 | R6: 9 | S6: 40 | T6: 30 | U6: 6 | V6: 3 | W6: 8 | X6: 24 | Z6: 47 | AA6: 99 | AB6: .475 | AC6: 18 | AD6: 46 | AE6: .391 | AF6: 29 | AG6: 35 | AH6: .829 | AI6: 17 | AJ6: 54 | AK6: 27 | AL6: 5 | AM6: 2 | AN6: 12 | AO6: 19
A7: 6 | B7: 6 | C7: 2021-01-01 | E7: ATL | F7: L | G7: 96 | H7: 114 | I7: 35 | J7: 86 | K7: .407 | L7: 7 | M7: 37 | N7: .189 | O7: 19 | P7: 23 | Q7: .826 | R7: 10 | S7: 45 | T7: 19 | U7: 6 | V7: 6 | W7: 15 | X7: 16 | Z7: 43 | AA7: 93 | AB7: .462 | AC7: 16 | AD7: 39 | AE7: .410 | AF7: 12 | AG7: 14 | AH7: .857 | AI7: 10 | AJ7: 48 | AK7: 24 | AL7: 8 | AM7: 3 | AN7: 9 | AO7: 20
A8: 7 | B8: 7 | C8: 2021-01-03 | E8: WAS | F8: L | G8: 122 | H8: 123 | I8: 40 | J8: 81 | K8: .494 | L8: 14 | M8: 32 | N8: .438 | O8: 28 | P8: 31 | Q8: .903 | R8: 7 | S8: 51 | T8: 25 | U8: 5 | V8: 9 | W8: 20 | X8: 24 | Z8: 43 | AA8: 104 | AB8: .413 | AC8: 12 | AD8: 33 | AE8: .364 | AF8: 25 | AG8: 34 | AH8: .735 | AI8: 13 | AJ8: 49 | AK8: 27 | AL8: 9 | AM8: 3 | AN8: 7 | AO8: 22
A9: 8 | B9: 8 | C9: 2021-01-05 | E9: UTA | F9: W | G9: 130 | H9: 96 | I9: 52 | J9: 93 | K9: .559 | L9: 14 | M9: 36 | N9: .389 | O9: 12 | P9: 16 | Q9: .750 | R9: 8 | S9: 51 | T9: 31 | U9: 11 | V9: 5 | W9: 12 | X9: 22 | Z9: 33 | AA9: 86 | AB9: .384 | AC9: 11 | AD9: 34 | AE9: .324 | AF9: 19 | AG9: 27 | AH9: .704 | AI9: 9 | AJ9: 41 | AK9: 17 | AL9: 6 | AM9: 3 | AN9: 15 | AO9: 18
A10: 9 | B10: 9 | C10: 2021-01-07 | E10: PHI | F10: W | G10: 122 | H10: 109 | I10: 44 | J10: 97 | K10: .454 | L10: 15 | M10: 37 | N10: .405 | O10: 19 | P10: 29 | Q10: .655 | R10: 11 | S10: 48 | T10: 30 | U10: 11 | V10: 7 | W10: 12 | X10: 17 | Z10: 41 | AA10: 87 | AB10: .471 | AC10: 9 | AD10: 26 | AE10: .346 | AF10: 18 | AG10: 20 | AH10: .900 | AI10: 4 | AJ10: 47 | AK10: 23 | AL10: 6 | AM10: 6 | AN10: 20 | AO10: 25
A11: 10 | B11: 10 | C11: 2021-01-08 | D11: @ | E11: MEM | F11: L | G11: 110 | H11: 115 | I11: 38 | J11: 81 | K11: .469 | L11: 14 | M11: 31 | N11: .452 | O11: 20 | P11: 21 | Q11: .952 | R11: 4 | S11: 42 | T11: 26 | U11: 6 | V11: 4 | W11: 20 | X11: 13 | Z11: 45 | AA11: 98 | AB11: .459 | AC11: 13 | AD11: 32 | AE11: .406 | AF11: 12 | AG11: 14 | AH11: .857 | AI11: 12 | AJ11: 46 | AK11: 29 | AL11: 14 | AM11: 6 | AN11: 12 | AO11: 18
A12: 11 | B12: 11 | C12: 2021-01-10 | E12: OKC | F12: L | G12: 116 | H12: 129 | I12: 43 | J12: 85 | K12: .506 | L12: 10 | M12: 34 | N12: .294 | O12: 20 | P12: 24 | Q12: .833 | R12: 6 | S12: 43 | T12: 23 | U12: 3 | V12: 2 | W12: 17 | X12: 18 | Z12: 49 | AA12: 90 | AB12: .544 | AC12: 15 | AD12: 39 | AE12: .385 | AF12: 16 | AG12: 17 | AH12: .941 | AI12: 3 | AJ12: 34 | AK12: 24 | AL12: 12 | AM12: 4 | AN12: 10 | AO12: 22
A13: 12 | B13: 12 | C13: 2021-01-12 | E13: DEN | F13: W | G13: 122 | H13: 116 | I13: 48 | J13: 79 | K13: .608 | L13: 16 | M13: 32 | N13: .500 | O13: 10 | P13: 15 | Q13: .667 | R13: 8 | S13: 41 | T13: 31 | U13: 6 | V13: 6 | W13: 18 | X13: 18 | Z13: 44 | AA13: 88 | AB13: .500 | AC13: 18 | AD13: 37 | AE13: .486 | AF13: 10 | AG13: 16 | AH13: .625 | AI13: 9 | AJ13: 32 | AK13: 28 | AL13: 12 | AM13: 5 | AN13: 13 | AO13: 18
A14: 13 | B14: 13 | C14: 2021-01-13 | D14: @ | E14: NYK | F14: W | G14: 116 | H14: 109 | I14: 44 | J14: 91 | K14: .484 | L14: 16 | M14: 40 | N14: .400 | O14: 12 | P14: 17 | Q14: .706 | R14: 12 | S14: 46 | T14: 29 | U14: 3 | V14: 5 | W14: 6 | X14: 12 | Z14: 44 | AA14: 92 | AB14: .478 | AC14: 11 | AD14: 28 | AE14: .393 | AF14: 10 | AG14: 12 | AH14: .833 | AI14: 12 | AJ14: 43 | AK14: 22 | AL14: 4 | AM14: 3 | AN14: 9 | AO14: 16
A15: 14 | B15: 14 | C15: 2021-01-16 | E15: ORL | F15: W | G15: 122 | H15: 115 | I15: 42 | J15: 78 | K15: .538 | L15: 16 | M15: 35 | N15: .457 | O15: 22 | P15: 25 | Q15: .880 | R15: 4 | S15: 41 | T15: 24 | U15: 9 | V15: 5 | W15: 19 | X15: 14 | Z15: 44 | AA15: 95 | AB15: .463 | AC15: 14 | AD15: 46 | AE15: .304 | AF15: 13 | AG15: 16 | AH15: .813 | AI15: 9 | AJ15: 38 | AK15: 28 | AL15: 13 | AM15: 4 | AN15: 12 | AO15: 19
A16: 15 | B16: 15 | C16: 2021-01-18 | E16: MIL | F16: W | G16: 125 | H16: 123 | I16: 46 | J16: 84 | K16: .548 | L16: 15 | M16: 31 | N16: .484 | O16: 18 | P16: 21 | Q16: .857 | R16: 7 | S16: 49 | T16: 26 | U16: 2 | V16: 5 | W16: 17 | X16: 19 | Z16: 46 | AA16: 105 | AB16: .438 | AC16: 11 | AD16: 38 | AE16: .289 | AF16: 20 | AG16: 24 | AH16: .833 | AI16: 11 | AJ16: 41 | AK16: 21 | AL16: 9 | AM16: 2 | AN16: 5 | AO16: 15
A17: 16 | B17: 16 | C17: 2021-01-20 | D17: @ | E17: CLE | F17: L | G17: 135 | H17: 147 | I17: 48 | J17: 106 | K17: .453 | L17: 15 | M17: 41 | N17: .366 | O17: 24 | P17: 27 | Q17: .889 | R17: 13 | S17: 52 | T17: 30 | U17: 8 | V17: 11 | W17: 16 | X17: 24 | Z17: 56 | AA17: 109 | AB17: .514 | AC17: 20 | AD17: 40 | AE17: .500 | AF17: 15 | AG17: 21 | AH17: .714 | AI17: 12 | AJ17: 50 | AK17: 29 | AL17: 10 | AM17: 6 | AN17: 14 | AO17: 21
A18: 17 | B18: 17 | C18: 2021-01-22 | D18: @ | E18: CLE | F18: L | G18: 113 | H18: 125 | I18: 42 | J18: 87 | K18: .483 | L18: 14 | M18: 43 | N18: .326 | O18: 15 | P18: 17 | Q18: .882 | R18: 6 | S18: 29 | T18: 23 | U18: 5 | V18: 8 | W18: 11 | X18: 25 | Z18: 45 | AA18: 87 | AB18: .517 | AC18: 8 | AD18: 25 | AE18: .320 | AF18: 27 | AG18: 32 | AH18: .844 | AI18: 13 | AJ18: 50 | AK18: 24 | AL18: 7 | AM18: 3 | AN18: 12 | AO18: 18
A19: 18 | B19: 18 | C19: 2021-01-23 | E19: MIA | F19: W | G19: 128 | H19: 124 | I19: 44 | J19: 83 | K19: .530 | L19: 19 | M19: 37 | N19: .514 | O19: 21 | P19: 26 | Q19: .808 | R19: 9 | S19: 47 | T19: 34 | U19: 0 | V19: 6 | W19: 16 | X19: 26 | Z19: 42 | AA19: 89 | AB19: .472 | AC19: 13 | AD19: 46 | AE19: .283 | AF19: 27 | AG19: 32 | AH19: .844 | AI19: 2 | AJ19: 31 | AK19: 29 | AL19: 7 | AM19: 1 | AN19: 8 | AO19: 23
A20: 19 | B20: 19 | C20: 2021-01-25 | E20: MIA | F20: W | G20: 98 | H20: 85 | I20: 34 | J20: 85 | K20: .400 | L20: 11 | M20: 38 | N20: .289 | O20: 19 | P20: 22 | Q20: .864 | R20: 6 | S20: 49 | T20: 24 | U20: 6 | V20: 5 | W20: 7 | X20: 18 | Z20: 31 | AA20: 84 | AB20: .369 | AC20: 11 | AD20: 43 | AE20: .256 | AF20: 12 | AG20: 17 | AH20: .706 | AI20: 8 | AJ20: 45 | AK20: 20 | AL20: 3 | AM20: 7 | AN20: 12 | AO20: 21
A21: 20 | B21: 20 | C21: 2021-01-27 | D21: @ | E21: ATL | F21: W | G21: 132 | H21: 128 | I21: 52 | J21: 98 | K21: .531 | L21: 11 | M21: 32 | N21: .344 | O21: 17 | P21: 20 | Q21: .850 | R21: 11 | S21: 36 | T21: 29 | U21: 7 | V21: 10 | W21: 9 | X21: 25 | Z21: 45 | AA21: 94 | AB21: .479 | AC21: 13 | AD21: 33 | AE21: .394 | AF21: 25 | AG21: 28 | AH21: .893 | AI21: 12 | AJ21: 37 | AK21: 29 | AL21: 3 | AM21: 7 | AN21: 9 | AO21: 18
I22: Team | J22: Team | K22: Team | L22: Team | M22: Team | N22: Team | O22: Team | P22: Team | Q22: Team | R22: Team | S22: Team | T22: Team | U22: Team | V22: Team | W22: Team | X22: Team | Z22: Opponent | AA22: Opponent | AB22: Opponent | AC22: Opponent | AD22: Opponent | AE22: Opponent | AF22: Opponent | AG22: Opponent | AH22: Opponent | AI22: Opponent | AJ22: Opponent | AK22: Opponent | AL22: Opponent | AM22: Opponent | AN22: Opponent | AO22: Opponent
A23: Rk | B23: G | C23: Date | E23: Opp | F23: W/L | G23: Tm | H23: Opp | I23: FG | J23: FGA | K23: FG% | L23: 3P | M23: 3PA | N23: 3P% | O23: FT | P23: FTA | Q23: FT% | R23: ORB | S23: TRB | T23: AST | U23: STL | V23: BLK | W23: TOV | X23: PF | Z23: FG | AA23: FGA | AB23: FG% | AC23: 3P | AD23: 3PA | AE23: 3P% | AF23: FT | AG23: FTA | AH23: FT% | AI23: ORB | AJ23: TRB | AK23: AST | AL23: STL | AM23: BLK | AN23: TOV | AO23: PF
A24: 21 | B24: 21 | C24: 2021-01-29 | D24: @ | E24: OKC | F24: W | G24: 147 | H24: 125 | I24: 57 | J24: 100 | K24: .570 | L24: 19 | M24: 45 | N24: .422 | O24: 14 | P24: 16 | Q24: .875 | R24: 10 | S24: 50 | T24: 33 | U24: 7 | V24: 4 | W24: 11 | X24: 25 | Z24: 40 | AA24: 86 | AB24: .465 | AC24: 16 | AD24: 38 | AE24: .421 | AF24: 29 | AG24: 34 | AH24: .853 | AI24: 6 | AJ24: 36 | AK24: 23 | AL24: 4 | AM24: 4 | AN24: 12 | AO24: 12
A25: 22 | B25: 22 | C25: 2021-01-31 | D25: @ | E25: WAS | F25: L | G25: 146 | H25: 149 | I25: 50 | J25: 88 | K25: .568 | L25: 19 | M25: 36 | N25: .528 | O25: 27 | P25: 33 | Q25: .818 | R25: 7 | S25: 45 | T25: 33 | U25: 6 | V25: 5 | W25: 17 | X25: 24 | Z25: 56 | AA25: 108 | AB25: .519 | AC25: 12 | AD25: 39 | AE25: .308 | AF25: 25 | AG25: 32 | AH25: .781 | AI25: 11 | AJ25: 39 | AK25: 24 | AL25: 10 | AM25: 2 | AN25: 7 | AO25: 22
A26: 23 | B26: 23 | C26: 2021-02-02 | E26: LAC | F26: W | G26: 124 | H26: 120 | I26: 45 | J26: 79 | K26: .570 | L26: 13 | M26: 31 | N26: .419 | O26: 21 | P26: 26 | Q26: .808 | R26: 6 | S26: 44 | T26: 25 | U26: 6 | V26: 4 | W26: 16 | X26: 17 | Z26: 45 | AA26: 99 | AB26: .455 | AC26: 15 | AD26: 36 | AE26: .417 | AF26: 15 | AG26: 17 | AH26: .882 | AI26: 11 | AJ26: 39 | AK26: 21 | AL26: 12 | AM26: 5 | AN26: 8 | AO26: 18
A27: 24 | B27: 24 | C27: 2021-02-05 | E27: TOR | F27: L | G27: 117 | H27: 123 | I27: 39 | J27: 80 | K27: .488 | L27: 17 | M27: 42 | N27: .405 | O27: 22 | P27: 29 | Q27: .759 | R27: 8 | S27: 40 | T27: 29 | U27: 5 | V27: 6 | W27: 18 | X27: 19 | Z27: 49 | AA27: 97 | AB27: .505 | AC27: 13 | AD27: 32 | AE27: .406 | AF27: 12 | AG27: 14 | AH27: .857 | AI27: 12 | AJ27: 41 | AK27: 22 | AL27: 10 | AM27: 6 | AN27: 10 | AO27: 25
A28: 25 | B28: 25 | C28: 2021-02-06 | D28: @ | E28: PHI | F28: L | G28: 108 | H28: 124 | I28: 39 | J28: 88 | K28: .443 | L28: 15 | M28: 41 | N28: .366 | O28: 15 | P28: 17 | Q28: .882 | R28: 8 | S28: 34 | T28: 21 | U28: 6 | V28: 3 | W28: 17 | X28: 18 | Z28: 48 | AA28: 94 | AB28: .511 | AC28: 10 | AD28: 27 | AE28: .370 | AF28: 18 | AG28: 22 | AH28: .818 | AI28: 13 | AJ28: 51 | AK28: 27 | AL28: 12 | AM28: 4 | AN28: 15 | AO28: 15
A29: 26 | B29: 26 | C29: 2021-02-09 | D29: @ | E29: DET | F29: L | G29: 111 | H29: 122 | I29: 43 | J29: 86 | K29: .500 | L29: 11 | M29: 30 | N29: .367 | O29: 14 | P29: 16 | Q29: .875 | R29: 8 | S29: 34 | T29: 30 | U29: 8 | V29: 6 | W29: 15 | X29: 22 | Z29: 47 | AA29: 84 | AB29: .560 | AC29: 13 | AD29: 29 | AE29: .448 | AF29: 15 | AG29: 21 | AH29: .714 | AI29: 7 | AJ29: 37 | AK29: 28 | AL29: 10 | AM29: 6 | AN29: 13 | AO29: 16
A30: 27 | B30: 27 | C30: 2021-02-10 | E30: IND | F30: W | G30: 104 | H30: 94 | I30: 32 | J30: 76 | K30: .421 | L30: 9 | M30: 31 | N30: .290 | O30: 31 | P30: 35 | Q30: .886 | R30: 9 | S30: 46 | T30: 20 | U30: 2 | V30: 5 | W30: 12 | X30: 20 | Z30: 36 | AA30: 92 | AB30: .391 | AC30: 15 | AD30: 38 | AE30: .395 | AF30: 7 | AG30: 11 | AH30: .636 | AI30: 10 | AJ30: 43 | AK30: 26 | AL30: 4 | AM30: 5 | AN30: 8 | AO30: 21
A31: 28 | B31: 28 | C31: 2021-02-13 | D31: @ | E31: GSW | F31: W | G31: 134 | H31: 117 | I31: 50 | J31: 93 | K31: .538 | L31: 16 | M31: 39 | N31: .410 | O31: 18 | P31: 20 | Q31: .900 | R31: 8 | S31: 45 | T31: 35 | U31: 9 | V31: 5 | W31: 13 | X31: 15 | Z31: 44 | AA31: 90 | AB31: .489 | AC31: 9 | AD31: 34 | AE31: .265 | AF31: 20 | AG31: 25 | AH31: .800 | AI31: 5 | AJ31: 37 | AK31: 25 | AL31: 6 | AM31: 6 | AN31: 13 | AO31: 15
A32: 29 | B32: 29 | C32: 2021-02-15 | D32: @ | E32: SAC | F32: W | G32: 136 | H32: 125 | I32: 51 | J32: 89 | K32: .573 | L32: 27 | M32: 47 | N32: .574 | O32: 7 | P32: 12 | Q32: .583 | R32: 9 | S32: 35 | T32: 31 | U32: 7 | V32: 4 | W32: 15 | X32: 16 | Z32: 51 | AA32: 96 | AB32: .531 | AC32: 12 | AD32: 33 | AE32: .364 | AF32: 11 | AG32: 13 | AH32: .846 | AI32: 15 | AJ32: 41 | AK32: 24 | AL32: 6 | AM32: 6 | AN32: 13 | AO32: 13
A33: 30 | B33: 30 | C33: 2021-02-16 | D33: @ | E33: PHO | F33: W | G33: 128 | H33: 124 | I33: 47 | J33: 82 | K33: .573 | L33: 20 | M33: 40 | N33: .500 | O33: 14 | P33: 15 | Q33: .933 | R33: 4 | S33: 37 | T33: 28 | U33: 4 | V33: 4 | W33: 10 | X33: 11 | Z33: 48 | AA33: 88 | AB33: .545 | AC33: 16 | AD33: 37 | AE33: .432 | AF33: 12 | AG33: 12 | AH33: 1.000 | AI33: 4 | AJ33: 34 | AK33: 28 | AL33: 7 | AM33: 3 | AN33: 6 | AO33: 15
A34: 31 | B34: 31 | C34: 2021-02-18 | D34: @ | E34: LAL | F34: W | G34: 109 | H34: 98 | I34: 38 | J34: 77 | K34: .494 | L34: 18 | M34: 39 | N34: .462 | O34: 15 | P34: 24 | Q34: .625 | R34: 8 | S34: 39 | T34: 23 | U34: 9 | V34: 3 | W34: 13 | X34: 18 | Z34: 40 | AA34: 83 | AB34: .482 | AC34: 8 | AD34: 30 | AE34: .267 | AF34: 10 | AG34: 14 | AH34: .714 | AI34: 10 | AJ34: 39 | AK34: 21 | AL34: 7 | AM34: 4 | AN34: 16 | AO34: 16
A35: 32 | B35: 32 | C35: 2021-02-21 | D35: @ | E35: LAC | F35: W | G35: 112 | H35: 108 | I35: 44 | J35: 92 | K35: .478 | L35: 11 | M35: 38 | N35: .289 | O35: 13 | P35: 19 | Q35: .684 | R35: 9 | S35: 40 | T35: 21 | U35: 10 | V35: 4 | W35: 6 | X35: 19 | Z35: 40 | AA35: 87 | AB35: .460 | AC35: 15 | AD35: 35 | AE35: .429 | AF35: 13 | AG35: 18 | AH35: .722 | AI35: 16 | AJ35: 52 | AK35: 24 | AL35: 3 | AM35: 4 | AN35: 16 | AO35: 17
A36: 33 | B36: 33 | C36: 2021-02-23 | E36: SAC | F36: W | G36: 127 | H36: 118 | I36: 44 | J36: 89 | K36: .494 | L36: 17 | M36: 40 | N36: .425 | O36: 22 | P36: 31 | Q36: .710 | R36: 10 | S36: 41 | T36: 30 | U36: 8 | V36: 5 | W36: 8 | X36: 16 | Z36: 45 | AA36: 87 | AB36: .517 | AC36: 15 | AD36: 31 | AE36: .484 | AF36: 13 | AG36: 19 | AH36: .684 | AI36: 5 | AJ36: 38 | AK36: 25 | AL36: 6 | AM36: 7 | AN36: 15 | AO36: 17
A37: 34 | B37: 34 | C37: 2021-02-25 | E37: ORL | F37: W | G37: 129 | H37: 92 | I37: 49 | J37: 92 | K37: .533 | L37: 20 | M37: 45 | N37: .444 | O37: 11 | P37: 14 | Q37: .786 | R37: 7 | S37: 51 | T37: 30 | U37: 11 | V37: 2 | W37: 13 | X37: 18 | Z37: 35 | AA37: 87 | AB37: .402 | AC37: 9 | AD37: 36 | AE37: .250 | AF37: 13 | AG37: 15 | AH37: .867 | AI37: 4 | AJ37: 35 | AK37: 19 | AL37: 8 | AM37: 1 | AN37: 18 | AO37: 10
A38: 35 | B38: 35 | C38: 2021-02-27 | E38: DAL | F38: L | G38: 98 | H38: 115 | I38: 35 | J38: 86 | K38: .407 | L38: 14 | M38: 44 | N38: .318 | O38: 14 | P38: 19 | Q38: .737 | R38: 14 | S38: 47 | T38: 21 | U38: 5 | V38: 4 | W38: 19 | X38: 16 | Z38: 45 | AA38: 86 | AB38: .523 | AC38: 14 | AD38: 36 | AE38: .389 | AF38: 11 | AG38: 17 | AH38: .647 | AI38: 6 | AJ38: 36 | AK38: 23 | AL38: 12 | AM38: 8 | AN38: 8 | AO38: 15
A39: 36 | B39: 36 | C39: 2021-03-01 | D39: @ | E39: SAS | F39: W | G39: 124 | H39: 113 | I39: 47 | J39: 100 | K39: .470 | L39: 17 | M39: 41 | N39: .415 | O39: 13 | P39: 17 | Q39: .765 | R39: 13 | S39: 51 | T39: 35 | U39: 6 | V39: 8 | W39: 5 | X39: 13 | Z39: 44 | AA39: 97 | AB39: .454 | AC39: 15 | AD39: 35 | AE39: .429 | AF39: 10 | AG39: 15 | AH39: .667 | AI39: 9 | AJ39: 48 | AK39: 30 | AL39: 2 | AM39: 3 | AN39: 9 | AO39: 16
A40: 37 | B40: 37 | C40: 2021-03-03 | D40: @ | E40: HOU | F40: W | G40: 132 | H40: 114 | I40: 49 | J40: 85 | K40: .576 | L40: 17 | M40: 35 | N40: .486 | O40: 17 | P40: 24 | Q40: .708 | R40: 10 | S40: 53 | T40: 33 | U40: 5 | V40: 1 | W40: 14 | X40: 24 | Z40: 38 | AA40: 91 | AB40: .418 | AC40: 18 | AD40: 43 | AE40: .419 | AF40: 20 | AG40: 28 | AH40: .714 | AI40: 12 | AJ40: 37 | AK40: 24 | AL40: 10 | AM40: 5 | AN40: 9 | AO40: 18
...

Sheet 湖人Regular Season Table (3)
A1: Rk | B1: G | C1: Date | D1: Column1 | E1: Opp | F1: W/L | G1: Tm | H1: Opp2 | I1: Team FG | J1: Team FGA | K1: Team FG% | L1: Team 3P | M1: Team 3PA | N1: Team 3P% | O1: Team FT | P1: Team FTA | Q1: Team FT% | R1: Team ORB | S1: Team TRB | T1: Team AST | U1: Team STL | V1: Team BLK | W1: Team TOV | X1: Team PF | Y1: 2 | Z1: Opponent FG | AA1: Opponent FGA | AB1: Opponent FG% | AC1: Opponent 3P | AD1: Opponent 3PA | AE1: Opponent 3P% | AF1: Opponent FT | AG1: Opponent FTA | AH1: Opponent FT% | AI1: Opponent ORB | AJ1: Opponent TRB | AK1: Opponent AST | AL1: Opponent STL | AM1: Opponent BLK | AN1: Opponent TOV | AO1: Opponent PF
A2: 1 | B2: 1 | C2: 2020-12-22 | E2: LAC | F2: L | G2: 109 | H2: 116 | I2: 38 | J2: 81 | K2: .469 | L2: 9 | M2: 29 | N2: .310 | O2: 24 | P2: 31 | Q2: .774 | R2: 8 | S2: 45 | T2: 22 | U2: 4 | V2: 2 | W2: 19 | X2: 20 | Z2: 44 | AA2: 93 | AB2: .473 | AC2: 14 | AD2: 40 | AE2: .350 | AF2: 14 | AG2: 19 | AH2: .737 | AI2: 11 | AJ2: 40 | AK2: 22 | AL2: 10 | AM2: 3 | AN2: 16 | AO2: 29
A3: 2 | B3: 2 | C3: 2020-12-25 | E3: DAL | F3: W | G3: 138 | H3: 115 | I3: 51 | J3: 91 | K3: .560 | L3: 19 | M3: 39 | N3: .487 | O3: 17 | P3: 24 | Q3: .708 | R3: 17 | S3: 53 | T3: 33 | U3: 9 | V3: 4 | W3: 16 | X3: 23 | Z3: 41 | AA3: 83 | AB3: .494 | AC3: 13 | AD3: 32 | AE3: .406 | AF3: 20 | AG3: 26 | AH3: .769 | AI3: 3 | AJ3: 27 | AK3: 20 | AL3: 13 | AM3: 3 | AN3: 9 | AO3: 22
A4: 3 | B4: 3 | C4: 2020-12-27 | E4: MIN | F4: W | G4: 127 | H4: 91 | I4: 50 | J4: 90 | K4: .556 | L4: 13 | M4: 35 | N4: .371 | O4: 14 | P4: 18 | Q4: .778 | R4: 5 | S4: 46 | T4: 32 | U4: 6 | V4: 14 | W4: 17 | X4: 19 | Z4: 38 | AA4: 103 | AB4: .369 | AC4: 6 | AD4: 35 | AE4: .171 | AF4: 9 | AG4: 14 | AH4: .643 | AI4: 17 | AJ4: 48 | AK4: 24 | AL4: 11 | AM4: 6 | AN4: 17 | AO4: 24
A5: 4 | B5: 4 | C5: 2020-12-28 | E5: POR | F5: L | G5: 107 | H5: 115 | I5: 41 | J5: 87 | K5: .471 | L5: 10 | M5: 27 | N5: .370 | O5: 15 | P5: 18 | Q5: .833 | R5: 6 | S5: 41 | T5: 20 | U5: 6 | V5: 5 | W5: 14 | X5: 14 | Z5: 43 | AA5: 92 | AB5: .467 | AC5: 16 | AD5: 46 | AE5: .348 | AF5: 13 | AG5: 15 | AH5: .867 | AI5: 7 | AJ5: 45 | AK5: 27 | AL5: 9 | AM5: 6 | AN5: 9 | AO5: 16
A6: 5 | B6: 5 | C6: 2020-12-30 | D6: @ | E6: SAS | F6: W | G6: 121 | H6: 107 | I6: 46 | J6: 82 | K6: .561 | L6: 14 | M6: 26 | N6: .538 | O6: 15 | P6: 20 | Q6: .750 | R6: 7 | S6: 47 | T6: 25 | U6: 4 | V6: 3 | W6: 17 | X6: 24 | Z6: 40 | AA6: 87 | AB6: .460 | AC6: 10 | AD6: 24 | AE6: .417 | AF6: 17 | AG6: 23 | AH6: .739 | AI6: 7 | AJ6: 39 | AK6: 25 | AL6: 8 | AM6: 4 | AN6: 10 | AO6: 18
A7: 6 | B7: 6 | C7: 2021-01-01 | D7: @ | E7: SAS | F7: W | G7: 109 | H7: 103 | I7: 41 | J7: 101 | K7: .406 | L7: 14 | M7: 33 | N7: .424 | O7: 13 | P7: 16 | Q7: .813 | R7: 16 | S7: 58 | T7: 27 | U7: 8 | V7: 7 | W7: 13 | X7: 20 | Z7: 36 | AA7: 85 | AB7: .424 | AC7: 13 | AD7: 34 | AE7: .382 | AF7: 18 | AG7: 26 | AH7: .692 | AI7: 8 | AJ7: 45 | AK7: 23 | AL7: 3 | AM7: 8 | AN7: 13 | AO7: 20
A8: 7 | B8: 7 | C8: 2021-01-03 | D8: @ | E8: MEM | F8: W | G8: 108 | H8: 94 | I8: 41 | J8: 89 | K8: .461 | L8: 12 | M8: 35 | N8: .343 | O8: 14 | P8: 19 | Q8: .737 | R8: 12 | S8: 49 | T8: 24 | U8: 9 | V8: 5 | W8: 10 | X8: 15 | Z8: 39 | AA8: 95 | AB8: .411 | AC8: 9 | AD8: 33 | AE8: .273 | AF8: 7 | AG8: 8 | AH8: .875 | AI8: 14 | AJ8: 50 | AK8: 23 | AL8: 6 | AM8: 3 | AN8: 11 | AO8: 18
A9: 8 | B9: 8 | C9: 2021-01-05 | D9: @ | E9: MEM | F9: W | G9: 94 | H9: 92 | I9: 38 | J9: 87 | K9: .437 | L9: 9 | M9: 31 | N9: .290 | O9: 9 | P9: 11 | Q9: .818 | R9: 9 | S9: 52 | T9: 24 | U9: 7 | V9: 8 | W9: 17 | X9: 14 | Z9: 36 | AA9: 87 | AB9: .414 | AC9: 10 | AD9: 26 | AE9: .385 | AF9: 10 | AG9: 13 | AH9: .769 | AI9: 5 | AJ9: 38 | AK9: 24 | AL9: 14 | AM9: 4 | AN9: 13 | AO9: 14
A10: 9 | B10: 9 | C10: 2021-01-07 | E10: SAS | F10: L | G10: 109 | H10: 118 | I10: 43 | J10: 86 | K10: .500 | L10: 10 | M10: 30 | N10: .333 | O10: 13 | P10: 21 | Q10: .619 | R10: 9 | S10: 48 | T10: 21 | U10: 2 | V10: 4 | W10: 13 | X10: 20 | Z10: 43 | AA10: 92 | AB10: .467 | AC10: 16 | AD10: 35 | AE10: .457 | AF10: 16 | AG10: 17 | AH10: .941 | AI10: 6 | AJ10: 40 | AK10: 28 | AL10: 4 | AM10: 3 | AN10: 6 | AO10: 15
A11: 10 | B11: 10 | C11: 2021-01-08 | E11: CHI | F11: W | G11: 117 | H11: 115 | I11: 41 | J11: 81 | K11: .506 | L11: 12 | M11: 29 | N11: .414 | O11: 23 | P11: 27 | Q11: .852 | R11: 10 | S11: 42 | T11: 21 | U11: 3 | V11: 8 | W11: 15 | X11: 15 | Z11: 46 | AA11: 91 | AB11: .505 | AC11: 10 | AD11: 26 | AE11: .385 | AF11: 13 | AG11: 14 | AH11: .929 | AI11: 9 | AJ11: 41 | AK11: 26 | AL11: 10 | AM11: 3 | AN11: 12 | AO11: 23
A12: 11 | B12: 11 | C12: 2021-01-10 | D12: @ | E12: HOU | F12: W | G12: 120 | H12: 102 | I12: 46 | J12: 91 | K12: .505 | L12: 10 | M12: 29 | N12: .345 | O12: 18 | P12: 24 | Q12: .750 | R12: 10 | S12: 49 | T12: 28 | U12: 13 | V12: 8 | W12: 16 | X12: 23 | Z12: 37 | AA12: 90 | AB12: .411 | AC12: 12 | AD12: 41 | AE12: .293 | AF12: 16 | AG12: 23 | AH12: .696 | AI12: 13 | AJ12: 43 | AK12: 22 | AL12: 7 | AM12: 8 | AN12: 21 | AO12: 22
A13: 12 | B13: 12 | C13: 2021-01-12 | D13: @ | E13: HOU | F13: W | G13: 117 | H13: 100 | I13: 42 | J13: 84 | K13: .500 | L13: 14 | M13: 32 | N13: .438 | O13: 19 | P13: 27 | Q13: .704 | R13: 11 | S13: 55 | T13: 26 | U13: 10 | V13: 12 | W13: 20 | X13: 18 | Z13: 38 | AA13: 97 | AB13: .392 | AC13: 12 | AD13: 40 | AE13: .300 | AF13: 12 | AG13: 16 | AH13: .750 | AI13: 10 | AJ13: 42 | AK13: 23 | AL13: 14 | AM13: 5 | AN13: 13 | AO13: 19
A14: 13 | B14: 13 | C14: 2021-01-13 | D14: @ | E14: OKC | F14: W | G14: 128 | H14: 99 | I14: 47 | J14: 95 | K14: .495 | L14: 17 | M14: 37 | N14: .459 | O14: 17 | P14: 22 | Q14: .773 | R14: 12 | S14: 50 | T14: 26 | U14: 6 | V14: 6 | W14: 9 | X14: 16 | Z14: 37 | AA14: 86 | AB14: .430 | AC14: 10 | AD14: 31 | AE14: .323 | AF14: 15 | AG14: 19 | AH14: .789 | AI14: 9 | AJ14: 42 | AK14: 23 | AL14: 4 | AM14: 6 | AN14: 11 | AO14: 21
A15: 14 | B15: 14 | C15: 2021-01-15 | E15: NOP | F15: W | G15: 112 | H15: 95 | I15: 39 | J15: 93 | K15: .419 | L15: 15 | M15: 37 | N15: .405 | O15: 19 | P15: 26 | Q15: .731 | R15: 13 | S15: 44 | T15: 31 | U15: 11 | V15: 6 | W15: 6 | X15: 16 | Z15: 41 | AA15: 86 | AB15: .477 | AC15: 9 | AD15: 29 | AE15: .310 | AF15: 4 | AG15: 8 | AH15: .500 | AI15: 10 | AJ15: 47 | AK15: 22 | AL15: 3 | AM15: 5 | AN15: 20 | AO15: 21
A16: 15 | B16: 15 | C16: 2021-01-18 | E16: GSW | F16: L | G16: 113 | H16: 115 | I16: 40 | J16: 83 | K16: .482 | L16: 9 | M16: 29 | N16: .310 | O16: 24 | P16: 33 | Q16: .727 | R16: 12 | S16: 50 | T16: 23 | U16: 6 | V16: 5 | W16: 16 | X16: 22 | Z16: 44 | AA16: 87 | AB16: .506 | AC16: 12 | AD16: 37 | AE16: .324 | AF16: 15 | AG16: 20 | AH16: .750 | AI16: 5 | AJ16: 32 | AK16: 31 | AL16: 8 | AM16: 3 | AN16: 13 | AO16: 27
A17: 16 | B17: 16 | C17: 2021-01-21 | D17: @ | E17: MIL | F17: W | G17: 113 | H17: 106 | I17: 41 | J17: 88 | K17: .466 | L17: 19 | M17: 37 | N17: .514 | O17: 12 | P17: 15 | Q17: .800 | R17: 6 | S17: 38 | T17: 25 | U17: 8 | V17: 8 | W17: 10 | X17: 14 | Z17: 44 | AA17: 87 | AB17: .506 | AC17: 9 | AD17: 28 | AE17: .321 | AF17: 9 | AG17: 12 | AH17: .750 | AI17: 5 | AJ17: 46 | AK17: 27 | AL17: 5 | AM17: 5 | AN17: 14 | AO17: 18
A18: 17 | B18: 17 | C18: 2021-01-23 | D18: @ | E18: CHI | F18: W | G18: 101 | H18: 90 | I18: 36 | J18: 79 | K18: .456 | L18: 4 | M18: 19 | N18: .211 | O18: 25 | P18: 31 | Q18: .806 | R18: 5 | S18: 42 | T18: 20 | U18: 7 | V18: 4 | W18: 18 | X18: 18 | Z18: 33 | AA18: 84 | AB18: .393 | AC18: 8 | AD18: 25 | AE18: .320 | AF18: 16 | AG18: 22 | AH18: .727 | AI18: 10 | AJ18: 45 | AK18: 18 | AL18: 8 | AM18: 1 | AN18: 18 | AO18: 28
A19: 18 | B19: 18 | C19: 2021-01-25 | D19: @ | E19: CLE | F19: W | G19: 115 | H19: 108 | I19: 42 | J19: 87 | K19: .483 | L19: 10 | M19: 32 | N19: .313 | O19: 21 | P19: 28 | Q19: .750 | R19: 15 | S19: 40 | T19: 21 | U19: 7 | V19: 7 | W19: 13 | X19: 23 | Z19: 40 | AA19: 86 | AB19: .465 | AC19: 9 | AD19: 21 | AE19: .429 | AF19: 19 | AG19: 22 | AH19: .864 | AI19: 15 | AJ19: 44 | AK19: 19 | AL19: 8 | AM19: 3 | AN19: 17 | AO19: 25
A20: 19 | B20: 19 | C20: 2021-01-27 | D20: @ | E20: PHI | F20: L | G20: 106 | H20: 107 | I20: 41 | J20: 86 | K20: .477 | L20: 8 | M20: 24 | N20: .333 | O20: 16 | P20: 25 | Q20: .640 | R20: 6 | S20: 37 | T20: 20 | U20: 5 | V20: 2 | W20: 11 | X20: 20 | Z20: 41 | AA20: 85 | AB20: .482 | AC20: 9 | AD20: 25 | AE20: .360 | AF20: 16 | AG20: 26 | AH20: .615 | AI20: 7 | AJ20: 38 | AK20: 24 | AL20: 10 | AM20: 7 | AN20: 11 | AO20: 24
A21: 20 | B21: 20 | C21: 2021-01-28 | D21: @ | E21: DET | F21: L | G21: 92 | H21: 107 | I21: 36 | J21: 88 | K21: .409 | L21: 12 | M21: 28 | N21: .429 | O21: 8 | P21: 12 | Q21: .667 | R21: 12 | S21: 44 | T21: 25 | U21: 2 | V21: 3 | W21: 11 | X21: 16 | Z21: 40 | AA21: 87 | AB21: .460 | AC21: 14 | AD21: 36 | AE21: .389 | AF21: 13 | AG21: 13 | AH21: 1.000 | AI21: 5 | AJ21: 38 | AK21: 27 | AL21: 4 | AM21: 2 | AN21: 8 | AO21: 18
I22: Team | J22: Team | K22: Team | L22: Team | M22: Team | N22: Team | O22: Team | P22: Team | Q22: Team | R22: Team | S22: Team | T22: Team | U22: Team | V22: Team | W22: Team | X22: Team | Z22: Opponent | AA22: Opponent | AB22: Opponent | AC22: Opponent | AD22: Opponent | AE22: Opponent | AF22: Opponent | AG22: Opponent | AH22: Opponent | AI22: Opponent | AJ22: Opponent | AK22: Opponent | AL22: Opponent | AM22: Opponent | AN22: Opponent | AO22: Opponent
A23: Rk | B23: G | C23: Date | E23: Opp | F23: W/L | G23: Tm | H23: Opp | I23: FG | J23: FGA | K23: FG% | L23: 3P | M23: 3PA | N23: 3P% | O23: FT | P23: FTA | Q23: FT% | R23: ORB | S23: TRB | T23: AST | U23: STL | V23: BLK | W23: TOV | X23: PF | Z23: FG | AA23: FGA | AB23: FG% | AC23: 3P | AD23: 3PA | AE23: 3P% | AF23: FT | AG23: FTA | AH23: FT% | AI23: ORB | AJ23: TRB | AK23: AST | AL23: STL | AM23: BLK | AN23: TOV | AO23: PF
A24: 21 | B24: 21 | C24: 2021-01-30 | D24: @ | E24: BOS | F24: W | G24: 96 | H24: 95 | I24: 37 | J24: 84 | K24: .440 | L24: 9 | M24: 31 | N24: .290 | O24: 13 | P24: 19 | Q24: .684 | R24: 13 | S24: 45 | T24: 20 | U24: 8 | V24: 4 | W24: 14 | X24: 15 | Z24: 40 | AA24: 82 | AB24: .488 | AC24: 6 | AD24: 21 | AE24: .286 | AF24: 9 | AG24: 14 | AH24: .643 | AI24: 9 | AJ24: 42 | AK24: 24 | AL24: 10 | AM24: 6 | AN24: 15 | AO24: 16
A25: 22 | B25: 22 | C25: 2021-02-01 | D25: @ | E25: ATL | F25: W | G25: 107 | H25: 99 | I25: 40 | J25: 77 | K25: .519 | L25: 7 | M25: 23 | N25: .304 | O25: 20 | P25: 24 | Q25: .833 | R25: 4 | S25: 31 | T25: 24 | U25: 10 | V25: 7 | W25: 11 | X25: 20 | Z25: 37 | AA25: 78 | AB25: .474 | AC25: 11 | AD25: 29 | AE25: .379 | AF25: 14 | AG25: 17 | AH25: .824 | AI25: 6 | AJ25: 36 | AK25: 27 | AL25: 8 | AM25: 3 | AN25: 17 | AO25: 21
A26: 23 | B26: 23 | C26: 2021-02-04 | E26: DEN | F26: W | G26: 114 | H26: 93 | I26: 46 | J26: 81 | K26: .568 | L26: 8 | M26: 24 | N26: .333 | O26: 14 | P26: 22 | Q26: .636 | R26: 8 | S26: 40 | T26: 29 | U26: 10 | V26: 7 | W26: 16 | X26: 19 | Z26: 36 | AA26: 92 | AB26: .391 | AC26: 8 | AD26: 28 | AE26: .286 | AF26: 13 | AG26: 15 | AH26: .867 | AI26: 16 | AJ26: 42 | AK26: 19 | AL26: 9 | AM26: 2 | AN26: 15 | AO26: 23
A27: 24 | B27: 24 | C27: 2021-02-06 | E27: DET | F27: W | G27: 135 | H27: 129 | I27: 51 | J27: 91 | K27: .560 | L27: 9 | M27: 19 | N27: .474 | O27: 24 | P27: 28 | Q27: .857 | R27: 9 | S27: 41 | T27: 32 | U27: 12 | V27: 5 | W27: 23 | X27: 24 | Z27: 45 | AA27: 94 | AB27: .479 | AC27: 16 | AD27: 42 | AE27: .381 | AF27: 23 | AG27: 28 | AH27: .821 | AI27: 9 | AJ27: 35 | AK27: 31 | AL27: 13 | AM27: 4 | AN27: 20 | AO27: 31
A28: 25 | B28: 25 | C28: 2021-02-08 | E28: OKC | F28: W | G28: 119 | H28: 112 | I28: 44 | J28: 95 | K28: .463 | L28: 9 | M28: 38 | N28: .237 | O28: 22 | P28: 29 | Q28: .759 | R28: 10 | S28: 59 | T28: 28 | U28: 7 | V28: 12 | W28: 15 | X28: 19 | Z28: 43 | AA28: 110 | AB28: .391 | AC28: 12 | AD28: 38 | AE28: .316 | AF28: 14 | AG28: 19 | AH28: .737 | AI28: 15 | AJ28: 55 | AK28: 23 | AL28: 6 | AM28: 4 | AN28: 12 | AO28: 23
A29: 26 | B29: 26 | C29: 2021-02-10 | E29: OKC | F29: W | G29: 114 | H29: 113 | I29: 42 | J29: 89 | K29: .472 | L29: 10 | M29: 35 | N29: .286 | O29: 20 | P29: 24 | Q29: .833 | R29: 6 | S29: 43 | T29: 22 | U29: 6 | V29: 6 | W29: 16 | X29: 15 | Z29: 47 | AA29: 100 | AB29: .470 | AC29: 7 | AD29: 31 | AE29: .226 | AF29: 12 | AG29: 14 | AH29: .857 | AI29: 7 | AJ29: 46 | AK29: 32 | AL29: 11 | AM29: 4 | AN29: 13 | AO29: 23
A30: 27 | B30: 27 | C30: 2021-02-12 | E30: MEM | F30: W | G30: 115 | H30: 105 | I30: 43 | J30: 85 | K30: .506 | L30: 6 | M30: 30 | N30: .200 | O30: 23 | P30: 33 | Q30: .697 | R30: 13 | S30: 47 | T30: 26 | U30: 9 | V30: 4 | W30: 18 | X30: 16 | Z30: 39 | AA30: 80 | AB30: .488 | AC30: 12 | AD30: 29 | AE30: .414 | AF30: 15 | AG30: 19 | AH30: .789 | AI30: 6 | AJ30: 33 | AK30: 31 | AL30: 9 | AM30: 2 | AN30: 17 | AO30: 25
A31: 28 | B31: 28 | C31: 2021-02-14 | D31: @ | E31: DEN | F31: L | G31: 105 | H31: 122 | I31: 40 | J31: 87 | K31: .460 | L31: 6 | M31: 28 | N31: .214 | O31: 19 | P31: 29 | Q31: .655 | R31: 8 | S31: 46 | T31: 27 | U31: 4 | V31: 4 | W31: 10 | X31: 26 | Z31: 39 | AA31: 85 | AB31: .459 | AC31: 19 | AD31: 47 | AE31: .404 | AF31: 25 | AG31: 34 | AH31: .735 | AI31: 9 | AJ31: 47 | AK31: 28 | AL31: 6 | AM31: 4 | AN31: 9 | AO31: 24
A32: 29 | B32: 29 | C32: 2021-02-16 | D32: @ | E32: MIN | F32: W | G32: 112 | H32: 104 | I32: 42 | J32: 77 | K32: .545 | L32: 11 | M32: 26 | N32: .423 | O32: 17 | P32: 21 | Q32: .810 | R32: 6 | S32: 38 | T32: 20 | U32: 8 | V32: 8 | W32: 18 | X32: 14 | Z32: 39 | AA32: 93 | AB32: .419 | AC32: 16 | AD32: 34 | AE32: .471 | AF32: 10 | AG32: 13 | AH32: .769 | AI32: 11 | AJ32: 38 | AK32: 26 | AL32: 11 | AM32: 4 | AN32: 15 | AO32: 27
A33: 30 | B33: 30 | C33: 2021-02-18 | E33: BRK | F33: L | G33: 98 | H33: 109 | I33: 40 | J33: 83 | K33: .482 | L33: 8 | M33: 30 | N33: .267 | O33: 10 | P33: 14 | Q33: .714 | R33: 10 | S33: 39 | T33: 21 | U33: 7 | V33: 4 | W33: 16 | X33: 16 | Z33: 38 | AA33: 77 | AB33: .494 | AC33: 18 | AD33: 39 | AE33: .462 | AF33: 15 | AG33: 24 | AH33: .625 | AI33: 8 | AJ33: 39 | AK33: 23 | AL33: 9 | AM33: 3 | AN33: 13 | AO33: 18
A34: 31 | B34: 31 | C34: 2021-02-20 | E34: MIA | F34: L | G34: 94 | H34: 96 | I34: 33 | J34: 84 | K34: .393 | L34: 13 | M34: 45 | N34: .289 | O34: 15 | P34: 17 | Q34: .882 | R34: 6 | S34: 43 | T34: 25 | U34: 5 | V34: 6 | W34: 14 | X34: 17 | Z34: 36 | AA34: 85 | AB34: .424 | AC34: 8 | AD34: 28 | AE34: .286 | AF34: 16 | AG34: 23 | AH34: .696 | AI34: 10 | AJ34: 49 | AK34: 24 | AL34: 8 | AM34: 3 | AN34: 14 | AO34: 20
A35: 32 | B35: 32 | C35: 2021-02-22 | E35: WAS | F35: L | G35: 124 | H35: 127 | I35: 49 | J35: 104 | K35: .471 | L35: 15 | M35: 44 | N35: .341 | O35: 11 | P35: 17 | Q35: .647 | R35: 12 | S35: 45 | T35: 29 | U35: 9 | V35: 11 | W35: 20 | X35: 29 | Z35: 47 | AA35: 96 | AB35: .490 | AC35: 9 | AD35: 25 | AE35: .360 | AF35: 24 | AG35: 33 | AH35: .727 | AI35: 5 | AJ35: 49 | AK35: 25 | AL35: 9 | AM35: 4 | AN35: 16 | AO35: 25
A36: 33 | B36: 33 | C36: 2021-02-24 | D36: @ | E36: UTA | F36: L | G36: 89 | H36: 114 | I36: 34 | J36: 85 | K36: .400 | L36: 8 | M36: 33 | N36: .242 | O36: 13 | P36: 20 | Q36: .650 | R36: 12 | S36: 45 | T36: 17 | U36: 5 | V36: 4 | W36: 14 | X36: 15 | Z36: 41 | AA36: 87 | AB36: .471 | AC36: 22 | AD36: 48 | AE36: .458 | AF36: 10 | AG36: 15 | AH36: .667 | AI36: 14 | AJ36: 53 | AK36: 28 | AL36: 7 | AM36: 1 | AN36: 12 | AO36: 16
A37: 34 | B37: 34 | C37: 2021-02-26 | E37: POR | F37: W | G37: 102 | H37: 93 | I37: 37 | J37: 88 | K37: .420 | L37: 7 | M37: 27 | N37: .259 | O37: 21 | P37: 28 | Q37: .750 | R37: 15 | S37: 52 | T37: 25 | U37: 9 | V37: 7 | W37: 9 | X37: 23 | Z37: 32 | AA37: 83 | AB37: .386 | AC37: 11 | AD37: 37 | AE37: .297 | AF37: 18 | AG37: 20 | AH37: .900 | AI37: 10 | AJ37: 45 | AK37: 19 | AL37: 5 | AM37: 5 | AN37: 15 | AO37: 21
A38: 35 | B38: 35 | C38: 2021-02-28 | E38: GSW | F38: W | G38: 117 | H38: 91 | I38: 40 | J38: 85 | K38: .471 | L38: 11 | M38: 31 | N38: .355 | O38: 26 | P38: 38 | Q38: .684 | R38: 14 | S38: 60 | T38: 22 | U38: 14 | V38: 6 | W38: 19 | X38: 21 | Z38: 35 | AA38: 86 | AB38: .407 | AC38: 8 | AD38: 34 | AE38: .235 | AF38: 13 | AG38: 19 | AH38: .684 | AI38: 3 | AJ38: 35 | AK38: 26 | AL38: 10 | AM38: 4 | AN38: 20 | AO38: 25
A39: 36 | B39: 36 | C39: 2021-03-02 | E39: PHO | F39: L | G39: 104 | H39: 114 | I39: 40 | J39: 79 | K39: .506 | L39: 11 | M39: 31 | N39: .355 | O39: 13 | P39: 17 | Q39: .765 | R39: 5 | S39: 34 | T39: 18 | U39: 6 | V39: 8 | W39: 12 | X39: 23 | Z39: 38 | AA39: 77 | AB39: .494 | AC39: 16 | AD39: 29 | AE39: .552 | AF39: 22 | AG39: 25 | AH39: .880 | AI39: 5 | AJ39: 35 | AK39: 30 | AL39: 5 | AM39: 7 | AN39: 13 | AO39: 16
A40: 37 | B40: 37 | C40: 2021-03-03 | D40: @ | E40: SAC | F40: L | G40: 120 | H40: 123 | I40: 49 | J40: 93 | K40: .527 | L40: 12 | M40: 27 | N40: .444 | O40: 10 | P40: 14 | Q40: .714 | R40: 15 | S40: 41 | T40: 27 | U40: 7 | V40: 3 | W40: 11 | X40: 19 | Z40: 48 | AA40: 80 | AB40: .600 | AC40: 12 | AD40: 25 | AE40: .480 | AF40: 15 | AG40: 19 | AH40: .789 | AI40: 6 | AJ40: 30 | AK40: 32 | AL40: 5 | AM40: 1 | AN40: 13 | AO40: 19
...

Sheet simulation
C1: 场次 | D1: 输赢 | E1: Away | F1: Home | G1: winner | H1: away spread | I1: home spread | J1: OU
C2: 1 | D2: =IF(E2=F2,0,IF(E2>F2,"1","-1")) -> -1 | E2: =ROUND(NORMINV(RAND(),最终结果!$I$8,最终结果!$E$8),0) -> 95 | F2: =ROUND(NORMINV(RAND(),最终结果!$I$12,最终结果!$E$12),0) -> 112 | G2: =IF(E2=F2,"OT",IF(E2>F2,"Away","Home")) -> Home | H2: =IF(E2+最终结果!$G$8>simulation!F2,"W","L") -> L | I2: =IF(F2+最终结果!$G$12>simulation!E2,"W","L") -> W | J2: =IF((E2+F2)>最终结果!$H$8,"Over","Under") -> Under
C3: 2 | D3: =IF(E3=F3,0,IF(E3>F3,"1","-1")) -> -1 | E3: =ROUND(NORMINV(RAND(),最终结果!$I$8,最终结果!$E$8),0) -> 104 | F3: =ROUND(NORMINV(RAND(),最终结果!$I$12,最终结果!$E$12),0) -> 114 | G3: =IF(E3=F3,"OT",IF(E3>F3,"Away","Home")) -> Home | H3: =IF(E3+最终结果!$G$8>simulation!F3,"W","L") -> L | I3: =IF(F3+最终结果!$G$12>simulation!E3,"W","L") -> W | J3: =IF((E3+F3)>最终结果!$H$8,"Over","Under") -> Under
C4: 3 | D4: =IF(E4=F4,0,IF(E4>F4,"1","-1")) -> -1 | E4: =ROUND(NORMINV(RAND(),最终结果!$I$8,最终结果!$E$8),0) -> 102 | F4: =ROUND(NORMINV(RAND(),最终结果!$I$12,最终结果!$E$12),0) -> 126 | G4: =IF(E4=F4,"OT",IF(E4>F4,"Away","Home")) -> Home | H4: =IF(E4+最终结果!$G$8>simulation!F4,"W","L") -> L | I4: =IF(F4+最终结果!$G$12>simulation!E4,"W","L") -> W | J4: =IF((E4+F4)>最终结果!$H$8,"Over","Under") -> Under
C5: 4 | D5: =IF(E5=F5,0,IF(E5>F5,"1","-1")) -> -1 | E5: =ROUND(NORMINV(RAND(),最终结果!$I$8,最终结果!$E$8),0) -> 113 | F5: =ROUND(NORMINV(RAND(),最终结果!$I$12,最终结果!$E$12),0) -> 128 | G5: =IF(E5=F5,"OT",IF(E5>F5,"Away","Home")) -> Home | H5: =IF(E5+最终结果!$G$8>simulation!F5,"W","L") -> L | I5: =IF(F5+最终结果!$G$12>simulation!E5,"W","L") -> W | J5: =IF((E5+F5)>最终结果!$H$8,"Over","Under") -> Over
C6: 5 | D6: =IF(E6=F6,0,IF(E6>F6,"1","-1")) -> 1 | E6: =ROUND(NORMINV(RAND(),最终结果!$I$8,最终结果!$E$8),0) -> 131 | F6: =ROUND(NORMINV(RAND(),最终结果!$I$12,最终结果!$E$12),0) -> 120 | G6: =IF(E6=F6,"OT",IF(E6>F6,"Away","Home")) -> Away | H6: =IF(E6+最终结果!$G$8>simulation!F6,"W","L") -> W | I6: =IF(F6+最终结果!$G$12>simulation!E6,"W","L") -> L | J6: =IF((E6+F6)>最终结果!$H$8,"Over","Under") -> Over
C7: 6 | D7: =IF(E7=F7,0,IF(E7>F7,"1","-1")) -> 1 | E7: =ROUND(NORMINV(RAND(),最终结果!$I$8,最终结果!$E$8),0) -> 126 | F7: =ROUND(NORMINV(RAND(),最终结果!$I$12,最终结果!$E$12),0) -> 121 | G7: =IF(E7=F7,"OT",IF(E7>F7,"Away","Home")) -> Away | H7: =IF(E7+最终结果!$G$8>simulation!F7,"W","L") -> W | I7: =IF(F7+最终结果!$G$12>simulation!E7,"W","L") -> L | J7: =IF((E7+F7)>最终结果!$H$8,"Over","Under") -> Over
C8: 7 | D8: =IF(E8=F8,0,IF(E8>F8,"1","-1")) -> -1 | E8: =ROUND(NORMINV(RAND(),最终结果!$I$8,最终结果!$E$8),0) -> 101 | F8: =ROUND(NORMINV(RAND(),最终结果!$I$12,最终结果!$E$12),0) -> 145 | G8: =IF(E8=F8,"OT",IF(E8>F8,"Away","Home")) -> Home | H8: =IF(E8+最终结果!$G$8>simulation!F8,"W","L") -> L | I8: =IF(F8+最终结果!$G$12>simulation!E8,"W","L") -> W | J8: =IF((E8+F8)>最终结果!$H$8,"Over","Under") -> Over
C9: 8 | D9: =IF(E9=F9,0,IF(E9>F9,"1","-1")) -> 1 | E9: =ROUND(NORMINV(RAND(),最终结果!$I$8,最终结果!$E$8),0) -> 125 | F9: =ROUND(NORMINV(RAND(),最终结果!$I$12,最终结果!$E$12),0) -> 124 | G9: =IF(E9=F9,"OT",IF(E9>F9,"Away","Home")) -> Away | H9: =IF(E9+最终结果!$G$8>simulation!F9,"W","L") -> W | I9: =IF(F9+最终结果!$G$12>simulation!E9,"W","L") -> L | J9: =IF((E9+F9)>最终结果!$H$8,"Over","Under") -> Over
C10: 9 | D10: =IF(E10=F10,0,IF(E10>F10,"1","-1")) -> 1 | E10: =ROUND(NORMINV(RAND(),最终结果!$I$8,最终结果!$E$8),0) -> 111 | F10: =ROUND(NORMINV(RAND(),最终结果!$I$12,最终结果!$E$12),0) -> 110 | G10: =IF(E10=F10,"OT",IF(E10>F10,"Away","Home")) -> Away | H10: =IF(E10+最终结果!$G$8>simulation!F10,"W","L") -> W | I10: =IF(F10+最终结果!$G$12>simulation!E10,"W","L") -> L | J10: =IF((E10+F10)>最终结果!$H$8,"Over","Under") -> Under
C11: 10 | D11: =IF(E11=F11,0,IF(E11>F11,"1","-1")) -> -1 | E11: =ROUND(NORMINV(RAND(),最终结果!$I$8,最终结果!$E$8),0) -> 85 | F11: =ROUND(NORMINV(RAND(),最终结果!$I$12,最终结果!$E$12),0) -> 113 | G11: =IF(E11=F11,"OT",IF(E11>F11,"Away","Home")) -> Home | H11: =IF(E11+最终结果!$G$8>simulation!F11,"W","L") -> L | I11: =IF(F11+最终结果!$G$12>simulation!E11,"W","L") -> W | J11: =IF((E11+F11)>最终结果!$H$8,"Over","Under") -> Under
C12: 11 | D12: =IF(E12=F12,0,IF(E12>F12,"1","-1")) -> -1 | E12: =ROUND(NORMINV(RAND(),最终结果!$I$8,最终结果!$E$8),0) -> 120 | F12: =ROUND(NORMINV(RAND(),最终结果!$I$12,最终结果!$E$12),0) -> 126 | G12: =IF(E12=F12,"OT",IF(E12>F12,"Away","Home")) -> Home | H12: =IF(E12+最终结果!$G$8>simulation!F12,"W","L") -> L | I12: =IF(F12+最终结果!$G$12>simulation!E12,"W","L") -> W | J12: =IF((E12+F12)>最终结果!$H$8,"Over","Under") -> Over
C13: 12 | D13: =IF(E13=F13,0,IF(E13>F13,"1","-1")) -> -1 | E13: =ROUND(NORMINV(RAND(),最终结果!$I$8,最终结果!$E$8),0) -> 90 | F13: =ROUND(NORMINV(RAND(),最终结果!$I$12,最终结果!$E$12),0) -> 110 | G13: =IF(E13=F13,"OT",IF(E13>F13,"Away","Home")) -> Home | H13: =IF(E13+最终结果!$G$8>simulation!F13,"W","L") -> L | I13: =IF(F13+最终结果!$G$12>simulation!E13,"W","L") -> W | J13: =IF((E13+F13)>最终结果!$H$8,"Over","Under") -> Under
... C1001: 1000 | D1001: =IF(E1001=F1001,0,IF(E1001>F1001,"1","-1")) -> 1 | E1001: =ROUND(NORMINV(RAND(),最终结果!$I$8,最终结果!$E$8),0) -> 118 | F1001: =ROUND(NORMINV(RAND(),最终结果!$I$12,最终结果!$E$12),0) -> 117 | G1001: =IF(E1001=F1001,"OT",IF(E1001>F1001,"Away","Home")) -> Away | H1001: =IF(E1001+最终结果!$G$8>simulation!F1001,"W","L") -> W | I1001: =IF(F1001+最终结果!$G$12>simulation!E1001,"W","L") -> L | J1001: =IF((E1001+F1001)>最终结果!$H$8,"Over","Under") -> Under

Sheet 最终结果
W1: Atlanta
W2: Boston
W3: Brooklyn
W4: Charlotte
W5: Chicago
W6: Cleveland
E7: St Dev | F7: TeamRanking | G7: Point spread | H7: OU | I7: project score | J7: Wins | K7: win pct | L7: win spread | M7: win spread % | N7: Over | O7: Under | P7: High | Q7: Low | W7: Dallas
C8: 客场队伍 | D8: Brooklyn | E8: =_xlfn.STDEV.P('篮网egular Season Table (2)'!G83:G154) -> 12.06329 | F8: =AVERAGE(VLOOKUP(D8,Table_0[[Team]:[Away]],6,FALSE)) -> 109 | G8: 3 | H8: 237 | I8: 113.5 | J8: =COUNTIFS(simulation!G:G,"Away") -> 398 | K8: =J8/(J8+J12)*100% -> 0.40862423 | L8: =COUNTIFS(simulation!H:H,"W") -> 468 | M8: =L8/(L8+L12) -> 0.47464503 | N8: =COUNTIF(simulation!J:J,"Over")/COUNTA(simulation!J2:J999999) -> 0.32 | O8: =COUNTIF(simulation!J:J,"Under")/COUNTA(simulation!J2:J999999) -> 0.68 | P8: =MAX(simulation!E:E) -> 152 | Q8: =MIN(simulation!E:E) -> 68 | W8: Denver
W9: Detroit
W10: Golden State
W11: Houston
C12: 主场队伍 | D12: LA Lakers | E12: =_xlfn.STDEV.P('湖人Regular Season Table (3)'!G83:G154) -> 11.841473 | F12: =AVERAGE(VLOOKUP(D12,Table_0[[Team]:[Home]],5,FALSE),VLOOKUP(最终结果!D8,Table_0__2[[Team]:[Away]],6,FALSE)) -> 114.05 | G12: -3 | H12: 237 | I12: 116.5 | J12: =COUNTIFS(simulation!G:G,"Home") -> 576 | K12: =J12/(J12+J8) -> 0.59137577 | L12: =COUNTIFS(simulation!I:I,"W") -> 518 | M12: =L12/(L12+L8) -> 0.52535497 | P12: =MAX(simulation!F:F) -> 159 | Q12: =MIN(simulation!F:F) -> 79 | W12: Indiana
W13: LA Clippers
W14: LA Lakers
W15: Memphis
G16: 湖人 | H16: 0.58 | W16: Miami
G17: 篮网 | H17: 0.42 | W17: Milwaukee
W18: Minnesota
W19: New Orleans
W20: New York
W21: Okla City
W22: Orlando
W23: Philadelphia
W24: Phoenix
W25: Portland
W26: Sacramento
W27: San Antonio
W28: Toronto
W29: Utah
W30: Washington
